/bin/sh: 1: /home/pi/AWS/Scripts/compile.py: Permission denied
Traceback (most recent call last):
  File "/home/pi/AWS/Scripts/outputs.py", line 31, in <module>
    df_kit = pd.read_csv(path + "kit.csv", sep=",", header=0, parse_dates=["Datetime"])
  File "/usr/local/lib/python3.7/dist-packages/pandas/io/parsers.py", line 686, in read_csv
    return _read(filepath_or_buffer, kwds)
  File "/usr/local/lib/python3.7/dist-packages/pandas/io/parsers.py", line 452, in _read
    parser = TextFileReader(fp_or_buf, **kwds)
  File "/usr/local/lib/python3.7/dist-packages/pandas/io/parsers.py", line 946, in __init__
    self._make_engine(self.engine)
  File "/usr/local/lib/python3.7/dist-packages/pandas/io/parsers.py", line 1178, in _make_engine
    self._engine = CParserWrapper(self.f, **self.options)
  File "/usr/local/lib/python3.7/dist-packages/pandas/io/parsers.py", line 2008, in __init__
    self._reader = parsers.TextReader(src, **kwds)
  File "pandas/_libs/parsers.pyx", line 382, in pandas._libs.parsers.TextReader.__cinit__
  File "pandas/_libs/parsers.pyx", line 674, in pandas._libs.parsers.TextReader._setup_parser_source
FileNotFoundError: [Errno 2] No such file or directory: '/home/pi/AWS/Data/kit.csv'
/bin/sh: 1: /home/pi/AWS/Scripts/compile.py: Permission denied
Traceback (most recent call last):
  File "/home/pi/AWS/Scripts/outputs.py", line 31, in <module>
    df_kit = pd.read_csv(path + "kit.csv", sep=",", header=0, parse_dates=["Datetime"])
  File "/usr/local/lib/python3.7/dist-packages/pandas/io/parsers.py", line 686, in read_csv
    return _read(filepath_or_buffer, kwds)
  File "/usr/local/lib/python3.7/dist-packages/pandas/io/parsers.py", line 452, in _read
    parser = TextFileReader(fp_or_buf, **kwds)
  File "/usr/local/lib/python3.7/dist-packages/pandas/io/parsers.py", line 946, in __init__
    self._make_engine(self.engine)
  File "/usr/local/lib/python3.7/dist-packages/pandas/io/parsers.py", line 1178, in _make_engine
    self._engine = CParserWrapper(self.f, **self.options)
  File "/usr/local/lib/python3.7/dist-packages/pandas/io/parsers.py", line 2008, in __init__
    self._reader = parsers.TextReader(src, **kwds)
  File "pandas/_libs/parsers.pyx", line 382, in pandas._libs.parsers.TextReader.__cinit__
  File "pandas/_libs/parsers.pyx", line 674, in pandas._libs.parsers.TextReader._setup_parser_source
FileNotFoundError: [Errno 2] No such file or directory: '/home/pi/AWS/Data/kit.csv'
/bin/sh: 1: /home/pi/AWS/Scripts/compile.py: Permission denied
Traceback (most recent call last):
  File "/home/pi/AWS/Scripts/outputs.py", line 31, in <module>
    df_kit = pd.read_csv(path + "kit.csv", sep=",", header=0, parse_dates=["Datetime"])
  File "/usr/local/lib/python3.7/dist-packages/pandas/io/parsers.py", line 686, in read_csv
    return _read(filepath_or_buffer, kwds)
  File "/usr/local/lib/python3.7/dist-packages/pandas/io/parsers.py", line 452, in _read
    parser = TextFileReader(fp_or_buf, **kwds)
  File "/usr/local/lib/python3.7/dist-packages/pandas/io/parsers.py", line 946, in __init__
    self._make_engine(self.engine)
  File "/usr/local/lib/python3.7/dist-packages/pandas/io/parsers.py", line 1178, in _make_engine
    self._engine = CParserWrapper(self.f, **self.options)
  File "/usr/local/lib/python3.7/dist-packages/pandas/io/parsers.py", line 2008, in __init__
    self._reader = parsers.TextReader(src, **kwds)
  File "pandas/_libs/parsers.pyx", line 382, in pandas._libs.parsers.TextReader.__cinit__
  File "pandas/_libs/parsers.pyx", line 674, in pandas._libs.parsers.TextReader._setup_parser_source
FileNotFoundError: [Errno 2] No such file or directory: '/home/pi/AWS/Data/kit.csv'
/bin/sh: 1: /home/pi/AWS/Scripts/compile.py: Permission denied
Traceback (most recent call last):
  File "/home/pi/AWS/Scripts/outputs.py", line 31, in <module>
    df_kit = pd.read_csv(path + "kit.csv", sep=",", header=0, parse_dates=["Datetime"])
  File "/usr/local/lib/python3.7/dist-packages/pandas/io/parsers.py", line 686, in read_csv
    return _read(filepath_or_buffer, kwds)
  File "/usr/local/lib/python3.7/dist-packages/pandas/io/parsers.py", line 452, in _read
    parser = TextFileReader(fp_or_buf, **kwds)
  File "/usr/local/lib/python3.7/dist-packages/pandas/io/parsers.py", line 946, in __init__
    self._make_engine(self.engine)
  File "/usr/local/lib/python3.7/dist-packages/pandas/io/parsers.py", line 1178, in _make_engine
    self._engine = CParserWrapper(self.f, **self.options)
  File "/usr/local/lib/python3.7/dist-packages/pandas/io/parsers.py", line 2008, in __init__
    self._reader = parsers.TextReader(src, **kwds)
  File "pandas/_libs/parsers.pyx", line 382, in pandas._libs.parsers.TextReader.__cinit__
  File "pandas/_libs/parsers.pyx", line 674, in pandas._libs.parsers.TextReader._setup_parser_source
FileNotFoundError: [Errno 2] No such file or directory: '/home/pi/AWS/Data/kit.csv'
/bin/sh: 1: /home/pi/AWS/Scripts/compile.py: Permission denied
Traceback (most recent call last):
  File "/home/pi/AWS/Scripts/outputs.py", line 31, in <module>
    df_kit = pd.read_csv(path + "kit.csv", sep=",", header=0, parse_dates=["Datetime"])
  File "/usr/local/lib/python3.7/dist-packages/pandas/io/parsers.py", line 686, in read_csv
    return _read(filepath_or_buffer, kwds)
  File "/usr/local/lib/python3.7/dist-packages/pandas/io/parsers.py", line 452, in _read
    parser = TextFileReader(fp_or_buf, **kwds)
  File "/usr/local/lib/python3.7/dist-packages/pandas/io/parsers.py", line 946, in __init__
    self._make_engine(self.engine)
  File "/usr/local/lib/python3.7/dist-packages/pandas/io/parsers.py", line 1178, in _make_engine
    self._engine = CParserWrapper(self.f, **self.options)
  File "/usr/local/lib/python3.7/dist-packages/pandas/io/parsers.py", line 2008, in __init__
    self._reader = parsers.TextReader(src, **kwds)
  File "pandas/_libs/parsers.pyx", line 382, in pandas._libs.parsers.TextReader.__cinit__
  File "pandas/_libs/parsers.pyx", line 674, in pandas._libs.parsers.TextReader._setup_parser_source
FileNotFoundError: [Errno 2] No such file or directory: '/home/pi/AWS/Data/kit.csv'
/bin/sh: 1: /home/pi/AWS/Scripts/compile.py: Permission denied
Traceback (most recent call last):
  File "/home/pi/AWS/Scripts/outputs.py", line 31, in <module>
    df_kit = pd.read_csv(path + "kit.csv", sep=",", header=0, parse_dates=["Datetime"])
  File "/usr/local/lib/python3.7/dist-packages/pandas/io/parsers.py", line 686, in read_csv
    return _read(filepath_or_buffer, kwds)
  File "/usr/local/lib/python3.7/dist-packages/pandas/io/parsers.py", line 452, in _read
    parser = TextFileReader(fp_or_buf, **kwds)
  File "/usr/local/lib/python3.7/dist-packages/pandas/io/parsers.py", line 946, in __init__
    self._make_engine(self.engine)
  File "/usr/local/lib/python3.7/dist-packages/pandas/io/parsers.py", line 1178, in _make_engine
    self._engine = CParserWrapper(self.f, **self.options)
  File "/usr/local/lib/python3.7/dist-packages/pandas/io/parsers.py", line 2008, in __init__
    self._reader = parsers.TextReader(src, **kwds)
  File "pandas/_libs/parsers.pyx", line 382, in pandas._libs.parsers.TextReader.__cinit__
  File "pandas/_libs/parsers.pyx", line 674, in pandas._libs.parsers.TextReader._setup_parser_source
FileNotFoundError: [Errno 2] No such file or directory: '/home/pi/AWS/Data/kit.csv'
/bin/sh: 1: /home/pi/AWS/Scripts/compile.py: Permission denied
Traceback (most recent call last):
  File "/home/pi/AWS/Scripts/outputs.py", line 31, in <module>
    df_kit = pd.read_csv(path + "kit.csv", sep=",", header=0, parse_dates=["Datetime"])
  File "/usr/local/lib/python3.7/dist-packages/pandas/io/parsers.py", line 686, in read_csv
    return _read(filepath_or_buffer, kwds)
  File "/usr/local/lib/python3.7/dist-packages/pandas/io/parsers.py", line 452, in _read
    parser = TextFileReader(fp_or_buf, **kwds)
  File "/usr/local/lib/python3.7/dist-packages/pandas/io/parsers.py", line 946, in __init__
    self._make_engine(self.engine)
  File "/usr/local/lib/python3.7/dist-packages/pandas/io/parsers.py", line 1178, in _make_engine
    self._engine = CParserWrapper(self.f, **self.options)
  File "/usr/local/lib/python3.7/dist-packages/pandas/io/parsers.py", line 2008, in __init__
    self._reader = parsers.TextReader(src, **kwds)
  File "pandas/_libs/parsers.pyx", line 382, in pandas._libs.parsers.TextReader.__cinit__
  File "pandas/_libs/parsers.pyx", line 674, in pandas._libs.parsers.TextReader._setup_parser_source
FileNotFoundError: [Errno 2] No such file or directory: '/home/pi/AWS/Data/kit.csv'
/bin/sh: 1: /home/pi/AWS/Scripts/compile.py: Permission denied
Traceback (most recent call last):
  File "/home/pi/AWS/Scripts/outputs.py", line 31, in <module>
    df_kit = pd.read_csv(path + "kit.csv", sep=",", header=0, parse_dates=["Datetime"])
  File "/usr/local/lib/python3.7/dist-packages/pandas/io/parsers.py", line 686, in read_csv
    return _read(filepath_or_buffer, kwds)
  File "/usr/local/lib/python3.7/dist-packages/pandas/io/parsers.py", line 452, in _read
    parser = TextFileReader(fp_or_buf, **kwds)
  File "/usr/local/lib/python3.7/dist-packages/pandas/io/parsers.py", line 946, in __init__
    self._make_engine(self.engine)
  File "/usr/local/lib/python3.7/dist-packages/pandas/io/parsers.py", line 1178, in _make_engine
    self._engine = CParserWrapper(self.f, **self.options)
  File "/usr/local/lib/python3.7/dist-packages/pandas/io/parsers.py", line 2008, in __init__
    self._reader = parsers.TextReader(src, **kwds)
  File "pandas/_libs/parsers.pyx", line 382, in pandas._libs.parsers.TextReader.__cinit__
  File "pandas/_libs/parsers.pyx", line 674, in pandas._libs.parsers.TextReader._setup_parser_source
FileNotFoundError: [Errno 2] No such file or directory: '/home/pi/AWS/Data/kit.csv'
